import {
    assert,
    assertEquals,
    assertRejects,
} from "jsr:@std/assert@0.225.3";
import { spy, assertSpyCall, assertSpyCalls, stub } from "jsr:@std/testing@0.225.1/mock";
import type { SupabaseClient, AuthError } from "npm:@supabase/supabase-js@2";

// Imports for refactored handler and mocks
import { mainHandler } from "./index.ts";
// Correcting potential import path if HandlerError is defined elsewhere or standard Error is sufficient
// If HandlerError is specifically needed and defined, ensure the path is correct.
// Assuming standard Error or AuthError is sufficient based on context.
// import { HandlerError } from '../api-subscriptions/handlers/current.ts'; 
import { HandlerError } from "../api-subscriptions/handlers/current.ts"; // Import HandlerError
import { createMockSupabaseClient } from "../_shared/test-utils.ts";
import type { Database } from "../types_db.ts";

// Test suite for the inner mainHandler
Deno.test("Logout Function - mainHandler Tests", async (t) => {

    await t.step("Successful logout should resolve without error", async () => {
        // Correctly access the client property from the mock setup
        const mockSupabaseClient = createMockSupabaseClient().client; 
        mockSupabaseClient.auth.signOut = () => {
            console.log("[Test Mock] signOut called, returning success");
            return Promise.resolve({ error: null });
        };

        try {
            await mainHandler(mockSupabaseClient);
            assert(true);
            console.log("[Test Success] mainHandler completed without error.");
        } catch (e) {
            console.error("[Test Failure] Error during successful logout test:", e);
            if (e instanceof Error) {
                assert(false, `Test failed: ${e.message}`);
            } else {
                assert(false, "Test failed with an unknown error type.");
            }
        }
    });

    await t.step("SignOut error should throw HandlerError", async () => {
        // Correctly access the client property
        const mockSupabaseClient = createMockSupabaseClient().client; 
        // Create an object mimicking AuthError structure
        const testError: Partial<AuthError> = { 
            name: 'AuthApiError', // Common name for AuthError
            message: "Sign out failed",
            status: 500,
        };

        mockSupabaseClient.auth.signOut = () => {
            console.log("[Test Mock] signOut called, returning error");
            // Ensure the return structure matches { error: AuthError | null }
            return Promise.resolve({ error: testError as AuthError }); 
        };

        await assertRejects(
            () => mainHandler(mockSupabaseClient),
            Error, // Expecting a rejection with an Error type
            "Sign out failed",
            "Expected mainHandler to reject due to sign-out error."
        );

        // Verify the error type and status property correctly
        try {
            await mainHandler(mockSupabaseClient);
            assert(false, "Expected mainHandler to throw but it did not.");
        } catch (e) {
            // Check if it's an instance of Error and has a status property
            if (e instanceof Error && 'status' in e) { 
                // Cast to AuthError or similar type that includes status for type safety
                assertEquals((e as AuthError).status, 500, `Expected error status 500, but got ${(e as AuthError).status}`);
                console.log(`[Test Success] Correctly caught error with status: ${(e as AuthError).status}`);
            } else {
                console.error("Caught error:", e); // Log the actual error for debugging
                assert(false, "Caught error is not of expected type or structure (should have 'status' property).");
            }
        }
    });

    await t.step("Unexpected signOut error should throw HandlerError (500)", async () => {
        // Correctly access the client property
        const mockSupabaseClient = createMockSupabaseClient().client; 
        const unexpectedError = new Error("Unexpected internal error");

        mockSupabaseClient.auth.signOut = () => {
            console.log("[Test Mock] signOut called, throwing unexpected error");
            throw unexpectedError; // Simulate an unexpected throw
        };

        await assertRejects(
            () => mainHandler(mockSupabaseClient),
            Error, // Expecting a rejection with an Error type
            "Unexpected internal error",
            "Expected mainHandler to reject due to an unexpected error."
        );

        // Verify the error message for unexpected errors
        try {
            await mainHandler(mockSupabaseClient);
            assert(false, "Expected mainHandler to throw but it did not.");
        } catch (e) {
            // Check that the caught error is the expected HandlerError with status 500
            if (e instanceof HandlerError) { // Type guard narrows 'e' to HandlerError
                assertEquals(e.message, "Unexpected internal error", `Expected error message did not match.`);
                assertEquals(e.status, 500, `Expected error status to be 500, but got ${e.status}`);
                // Optionally check that the cause is the original error
                assert(e.cause === unexpectedError, "Expected HandlerError.cause to be the original unexpectedError"); 
                console.log(`[Test Success] Correctly caught HandlerError wrapping unexpected error: ${e.message}, Status: ${e.status}`);
            } else {
                // Log the actual error if it's not a HandlerError
                console.error("Caught unexpected error type:", e); 
                const errorName = typeof e === 'object' && e !== null && e.constructor ? e.constructor.name : typeof e;
                assert(false, `Caught error is not an instance of HandlerError. Type: ${errorName}`);
            }
        }
    });
}); 